Workbook

Sheet 1. Assumptions
B1: 🎯 DEEPAK POD | JUNE 2026 TARGET MODEL — Assumptions & Parameters
B2: COLOUR KEY: BLUE TEXT = Input — change freely | BLACK = Formula (auto) | AMBER BG = Estimate/Historical | GREEN BG = On Track | RED BG = Alert / Shortfall
B4: SECTION A — THE GOAL (June 2026)
B5: Parameter | C5: Value | D5: Notes
B6: Net PO Target (₹L) | C6: 100 | D6: Goal: 1 Crore Net PO for June
B7: Exit Budget — max (₹L) | C7: 5 | D7: CC closures + Resignations + PO closures: keep under 5L
B8: Gross PO Needed (₹L) | C8: =C6+C7 -> 105 | D8: Gross PO = Net Target + Exit Budget (auto-calculated)
B9: Working Days — June | C9: 22 | D9: Mon-Fri June 1-30 (adjust here if there are holidays)
B10: Target Selects / Month | C10: 50 | D10: About 2.5 selects per working day across all customers
B11: Sel -> Onboard Rate (%) | C11: 0.8 | D11: Historical: 80% of selects actually onboard
B12: Target Onboards / Month | C12: =C11*C10 -> 40 | D12: Onboards = Selects multiplied by OB Rate (auto)
B13: Avg PO per OB — blended (Rs L) | C13: =C8/C12 -> 2.625 | D13: Gross PO Needed divided by total OBs (auto)
B14: Repeat Demand % (global) | C14: 0.8 | D14: 80% of demands are REPEAT roles (same profile, known JD) — submit 3-4 profiles directly. 20% are NEW demands — submit 2 first, wait for client validation, then send 2 more. Change this % if your customer mix shifts.
B15: Revenue Model OBs (from customer build) | C15: =SUM(G25:G29) -> 60 | D15: =IF(SUM(G25:G29)=C12,"Consistent with top-down target","WARNING: Revenue build needs "&SUM(G25:G29)&" OBs but top-down target (C12) = "&C12&" OBs. Update C10 to "&CEILING(SUM(G25:G29)/C11,1)&" selects to align.") -> WARNING: Revenue build needs 60 OBs but top-down target (C12) = 40 OBs. Update C10 to 75 selects to align.
B16: Revenue Model Selects Needed | C16: =CEILING(SUM(G25:G29)/C11,1) -> 75 | D16: Compare this to C10 (Target Selects). If different, the revenue targets and the select target are inconsistent — update C10 to match.
B23: SECTION B — CUSTOMER TARGETS (June 2026 | All ₹ in Lakhs)
B24: Customer | C24: Net PO Target ₹L | D24: Exit Alloc ₹L | E24: Gross PO Target ₹L | F24: Avg PO per OB ₹L | G24: OBs Needed | H24: Selects Needed | I24: Daily Selects | J24: Daily OBs | K24: May Carry- Fwd OBs
B25: Deloitte MB | C25: 40 | D25: 1.5 | E25: =C25+D25 -> 41.5 | F25: 1.52 | G25: =IFERROR(CEILING(E25/F25,1),0) -> 28 | H25: =IFERROR(CEILING(G25/C$11,1),0) -> 35 | I25: =IFERROR(ROUND(H25/C$9,2),0) -> 1.59 | J25: =IFERROR(ROUND(G25/C$9,2),0) -> 1.27 | K25: 2
B26: DTICI | C26: 25 | D26: 1.5 | E26: =C26+D26 -> 26.5 | F26: 1.8 | G26: =IFERROR(CEILING(E26/F26,1),0) -> 15 | H26: =IFERROR(CEILING(G26/C$11,1),0) -> 19 | I26: =IFERROR(ROUND(H26/C$9,2),0) -> 0.86 | J26: =IFERROR(ROUND(G26/C$9,2),0) -> 0.68 | K26: 2
B27: BSH | C27: 20 | D27: 1 | E27: =C27+D27 -> 21 | F27: 2.61 | G27: =IFERROR(CEILING(E27/F27,1),0) -> 9 | H27: =IFERROR(CEILING(G27/C$11,1),0) -> 12 | I27: =IFERROR(ROUND(H27/C$9,2),0) -> 0.55 | J27: =IFERROR(ROUND(G27/C$9,2),0) -> 0.41 | K27: 1
B28: Arcelor Mittal | C28: 10 | D28: 0.5 | E28: =C28+D28 -> 10.5 | F28: 3.23 | G28: =IFERROR(CEILING(E28/F28,1),0) -> 4 | H28: =IFERROR(CEILING(G28/C$11,1),0) -> 5 | I28: =IFERROR(ROUND(H28/C$9,2),0) -> 0.23 | J28: =IFERROR(ROUND(G28/C$9,2),0) -> 0.18 | K28: 1
B29: Pure Storage | C29: 5 | D29: 0.5 | E29: =C29+D29 -> 5.5 | F29: 1.5 | G29: =IFERROR(CEILING(E29/F29,1),0) -> 4 | H29: =IFERROR(CEILING(G29/C$11,1),0) -> 5 | I29: =IFERROR(ROUND(H29/C$9,2),0) -> 0.23 | J29: =IFERROR(ROUND(G29/C$9,2),0) -> 0.18 | K29: 0
B30: TOTAL | C30: =SUM(C25:C29) -> 100 | D30: =SUM(D25:D29) -> 5 | E30: =SUM(E25:E29) -> 105 | F30: ↑ Check ≈ blended avg | G30: =SUM(G25:G29) -> 60 | H30: =SUM(H25:H29) -> 76 | I30: =SUM(I25:I29) -> 3.46 | J30: =SUM(J25:J29) -> 2.72 | K30: =SUM(K25:K29) -> 6
B33: SECTION B2 — DEMAND CLASSIFICATION (This drives Submissions. Change the blue cells. Repeat = familiar roles, submit 3-4 directly. New = first-time roles, submit 2, wait for validation, then 2 more.)
B34: Customer | C34: Open Demand Pool — June ✏️ | D34: Repeat Demand % ✏️ | E34: Subs / Repeat Demand ✏️ | F34: Subs / New Phase 1 ✏️ | G34: Subs / New Phase 2 (after validation) ✏️ | H34: Avg Subs / Demand (auto) | I34: Monthly Subs Target (auto) | J34: Daily Subs Target (auto) | K34: Target Interviews / Day ✏️ ← SET THIS | L34: Monthly Interviews (auto = J × WD)
B35: Deloitte MB | C35: 250 | D35: 0.8 | E35: 4 | F35: 2 | G35: 2 | H35: =ROUND(D35*E35+(1-D35)*(F35+G35),1) -> 4 | I35: =CEILING(C35*H35,1) -> 1000 | J35: =CEILING(I35/C$9,1) -> 46 | K35: 20 | L35: =K35*C$9 -> 440
B36: DTICI | C36: 200 | D36: 0.8 | E36: 4 | F36: 2 | G36: 2 | H36: =ROUND(D36*E36+(1-D36)*(F36+G36),1) -> 4 | I36: =CEILING(C36*H36,1) -> 800 | J36: =CEILING(I36/C$9,1) -> 37 | K36: 14 | L36: =K36*C$9 -> 308
B37: BSH | C37: 60 | D37: 0.8 | E37: 4 | F37: 2 | G37: 2 | H37: =ROUND(D37*E37+(1-D37)*(F37+G37),1) -> 4 | I37: =CEILING(C37*H37,1) -> 240 | J37: =CEILING(I37/C$9,1) -> 11 | K37: 7 | L37: =K37*C$9 -> 154
B38: Arcelor Mittal | C38: 50 | D38: 0.8 | E38: 4 | F38: 2 | G38: 2 | H38: =ROUND(D38*E38+(1-D38)*(F38+G38),1) -> 4 | I38: =CEILING(C38*H38,1) -> 200 | J38: =CEILING(I38/C$9,1) -> 10 | K38: 5 | L38: =K38*C$9 -> 110
B39: Pure Storage | C39: 25 | D39: 0.8 | E39: 4 | F39: 2 | G39: 2 | H39: =ROUND(D39*E39+(1-D39)*(F39+G39),1) -> 4 | I39: =CEILING(C39*H39,1) -> 100 | J39: =CEILING(I39/C$9,1) -> 5 | K39: 4 | L39: =K39*C$9 -> 88
B40: TOTAL | C40: =SUM(C35:C39) -> 585 | I40: =SUM(I35:I39) -> 2340 | J40: =SUM(J35:J39) -> 109 | K40: =SUM(K35:K39) -> 50 | L40: =SUM(L35:L39) -> 1100 | M40: Total interviews/day should be 50-55. Sub total should be close to recruiter capacity (16x6=96/day).
B43: SECTION C — FUNNEL ASSUMPTIONS (Interviews come from Section B2 direct target. Sub->Int% TARGET below is now a REQUIRED RATE — the rate the team must hit to generate those interviews from subs.)
B44: Customer | C44: Sub->Interview 6M Historical | D44: Sub->Interview Required Rate (auto-calculated) | E44: Interview->Select 6M Historical | F44: Interview->Select June TARGET ✏️ | G44: Sel->OB TAT Historical (days) | H44: Sel->OB TAT June TARGET ✏️ | I44: Screen Reject Rate (est.) ✏️ | J44: Monthly Subs (from Demand Pool) | K44: Monthly Interviews (from B2 direct target) | L44: Expected Selects from Demand Subs
B45: Deloitte MB | C45: 0.26 | D45: =IFERROR(ROUND('1. Assumptions'!L35/'1. Assumptions'!I35,3),0) -> 0.44 | E45: 0.048 | F45: 0.08 | G45: 11 | H45: 8 | I45: 0.4 | J45: ='1. Assumptions'!I35 -> 1000 | K45: ='1. Assumptions'!L35 -> 440 | L45: =IFERROR(FLOOR(K45*F45,1),0) -> 35
B46: DTICI | C46: 0.177 | D46: =IFERROR(ROUND('1. Assumptions'!L36/'1. Assumptions'!I36,3),0) -> 0.385 | E46: 0.154 | F46: 0.18 | G46: 9 | H46: 7 | I46: 0.35 | J46: ='1. Assumptions'!I36 -> 800 | K46: ='1. Assumptions'!L36 -> 308 | L46: =IFERROR(FLOOR(K46*F46,1),0) -> 55
B47: BSH | C47: 0.347 | D47: =IFERROR(ROUND('1. Assumptions'!L37/'1. Assumptions'!I37,3),0) -> 0.642 | E47: 0.059 | F47: 0.1 | G47: 8 | H47: 6 | I47: 0.3 | J47: ='1. Assumptions'!I37 -> 240 | K47: ='1. Assumptions'!L37 -> 154 | L47: =IFERROR(FLOOR(K47*F47,1),0) -> 15
B48: Arcelor Mittal | C48: 0.106 | D48: =IFERROR(ROUND('1. Assumptions'!L38/'1. Assumptions'!I38,3),0) -> 0.55 | E48: 0.043 | F48: 0.07 | G48: 16 | H48: 12 | I48: 0.45 | J48: ='1. Assumptions'!I38 -> 200 | K48: ='1. Assumptions'!L38 -> 110 | L48: =IFERROR(FLOOR(K48*F48,1),0) -> 7
B49: Pure Storage | C49: 0.2 | D49: =IFERROR(ROUND('1. Assumptions'!L39/'1. Assumptions'!I39,3),0) -> 0.88 | E49: 0.05 | F49: 0.08 | G49: 12 | H49: 10 | I49: 0.4 | J49: ='1. Assumptions'!I39 -> 100 | K49: ='1. Assumptions'!L39 -> 88 | L49: =IFERROR(FLOOR(K49*F49,1),0) -> 7
B53: SECTION D — RECRUITER SETUP (16 Recruiters | Target 6 Submissions / Recruiter / Day)
B54: Recruiter Name | C54: Subs/Day Target ✏️ | D54: Primary Customer ✏️ | E54: Secondary Customer ✏️ | F54: Monthly Subs Target (=Target×WD) | G54: Notes
...

Sheet 2. June Daily Rhythm
B1: 📅 DEEPAK POD | JUNE 2026 DAILY TARGET RHYTHM — Updated daily by Deepak / Pod Leads
B2: BLUE = Targets (auto from assumptions) | For each working day: check demands, confirm subs are flowing, interview count, selects, OBs | Front-loaded OBs = May selections that join in June based on TAT
B4: JUNE SUMMARY — TARGET vs PLAN (links to Assumptions Sheet 1)
B5: Metric | C5: TOTAL | D5: Del MB | E5: DTICI | F5: BSH | G5: Arcel | H5: PureStr
B6: Monthly Subs Needed | C6: =D6+E6+F6+G6+H6 -> 2340 | D6: ='1. Assumptions'!J45 -> 1000 | E6: ='1. Assumptions'!J46 -> 800 | F6: ='1. Assumptions'!J47 -> 240 | G6: ='1. Assumptions'!J48 -> 200 | H6: ='1. Assumptions'!J49 -> 100
B7: Monthly Interviews Needed | C7: =D7+E7+F7+G7+H7 -> 1100 | D7: ='1. Assumptions'!K45 -> 440 | E7: ='1. Assumptions'!K46 -> 308 | F7: ='1. Assumptions'!K47 -> 154 | G7: ='1. Assumptions'!K48 -> 110 | H7: ='1. Assumptions'!K49 -> 88
B8: Monthly Selects Target | C8: =D8+E8+F8+G8+H8 -> 76 | D8: ='1. Assumptions'!H25 -> 35 | E8: ='1. Assumptions'!H26 -> 19 | F8: ='1. Assumptions'!H27 -> 12 | G8: ='1. Assumptions'!H28 -> 5 | H8: ='1. Assumptions'!H29 -> 5
B9: Monthly Onboards Target | C9: =D9+E9+F9+G9+H9 -> 60 | D9: ='1. Assumptions'!G25 -> 28 | E9: ='1. Assumptions'!G26 -> 15 | F9: ='1. Assumptions'!G27 -> 9 | G9: ='1. Assumptions'!G28 -> 4 | H9: ='1. Assumptions'!G29 -> 4
B12: DAILY TARGET TRACKER — Fill ACTUAL columns daily. Status auto-updates.
B13: Customer / Metric | C13: Monthly Target | D13: 46174 | E13: 46175 | F13: 46176 | G13: 46177 | H13: 46178 | I13: 46181 | J13: 46182 | K13: 46183 | L13: 46184 | M13: 46185 | N13: 46188 | O13: 46189 | P13: 46190 | Q13: 46191 | R13: 46192 | S13: 46195 | T13: 46196 | U13: 46197 | V13: 46198 | W13: 46199 | X13: 46202 | Y13: 46203 | Z13: Jun Total
B14: DELOITTE MB
B15: Demand Pool | C15: ='1. Assumptions'!C35 -> 250 | D15: Repeat 80%: 200 demands x 4 subs = 800 subs | New 20%: 50 demands x (2+2) subs = 200 subs (Phase 1 days 1-11 / Phase 2 days 12-22 after validation)
B16: Subs / Day | C16: ='1. Assumptions'!J45 -> 1000 | D16: =CEILING('1. Assumptions'!J45/'1. Assumptions'!C9,1) -> 46 | E16: =CEILING('1. Assumptions'!J45/'1. Assumptions'!C9,1) -> 46 | F16: =CEILING('1. Assumptions'!J45/'1. Assumptions'!C9,1) -> 46 | G16: =CEILING('1. Assumptions'!J45/'1. Assumptions'!C9,1) -> 46 | H16: =CEILING('1. Assumptions'!J45/'1. Assumptions'!C9,1) -> 46 | I16: =CEILING('1. Assumptions'!J45/'1. Assumptions'!C9,1) -> 46 | J16: =CEILING('1. Assumptions'!J45/'1. Assumptions'!C9,1) -> 46 | K16: =CEILING('1. Assumptions'!J45/'1. Assumptions'!C9,1) -> 46 | L16: =CEILING('1. Assumptions'!J45/'1. Assumptions'!C9,1) -> 46 | M16: =CEILING('1. Assumptions'!J45/'1. Assumptions'!C9,1) -> 46 | N16: =CEILING('1. Assumptions'!J45/'1. Assumptions'!C9,1) -> 46 | O16: =CEILING('1. Assumptions'!J45/'1. Assumptions'!C9,1) -> 46 | P16: =CEILING('1. Assumptions'!J45/'1. Assumptions'!C9,1) -> 46 | Q16: =CEILING('1. Assumptions'!J45/'1. Assumptions'!C9,1) -> 46 | R16: =CEILING('1. Assumptions'!J45/'1. Assumptions'!C9,1) -> 46 | S16: =CEILING('1. Assumptions'!J45/'1. Assumptions'!C9,1) -> 46 | T16: =CEILING('1. Assumptions'!J45/'1. Assumptions'!C9,1) -> 46 | U16: =CEILING('1. Assumptions'!J45/'1. Assumptions'!C9,1) -> 46 | V16: =CEILING('1. Assumptions'!J45/'1. Assumptions'!C9,1) -> 46 | W16: =CEILING('1. Assumptions'!J45/'1. Assumptions'!C9,1) -> 46 | X16: =CEILING('1. Assumptions'!J45/'1. Assumptions'!C9,1) -> 46 | Y16: =CEILING('1. Assumptions'!J45/'1. Assumptions'!C9,1) -> 46 | Z16: =C16 -> 1000
B17: Interviews / Day | C17: ='1. Assumptions'!K45 -> 440 | D17: =CEILING('1. Assumptions'!K45/'1. Assumptions'!C9,1) -> 20 | E17: =CEILING('1. Assumptions'!K45/'1. Assumptions'!C9,1) -> 20 | F17: =CEILING('1. Assumptions'!K45/'1. Assumptions'!C9,1) -> 20 | G17: =CEILING('1. Assumptions'!K45/'1. Assumptions'!C9,1) -> 20 | H17: =CEILING('1. Assumptions'!K45/'1. Assumptions'!C9,1) -> 20 | I17: =CEILING('1. Assumptions'!K45/'1. Assumptions'!C9,1) -> 20 | J17: =CEILING('1. Assumptions'!K45/'1. Assumptions'!C9,1) -> 20 | K17: =CEILING('1. Assumptions'!K45/'1. Assumptions'!C9,1) -> 20 | L17: =CEILING('1. Assumptions'!K45/'1. Assumptions'!C9,1) -> 20 | M17: =CEILING('1. Assumptions'!K45/'1. Assumptions'!C9,1) -> 20 | N17: =CEILING('1. Assumptions'!K45/'1. Assumptions'!C9,1) -> 20 | O17: =CEILING('1. Assumptions'!K45/'1. Assumptions'!C9,1) -> 20 | P17: =CEILING('1. Assumptions'!K45/'1. Assumptions'!C9,1) -> 20 | Q17: =CEILING('1. Assumptions'!K45/'1. Assumptions'!C9,1) -> 20 | R17: =CEILING('1. Assumptions'!K45/'1. Assumptions'!C9,1) -> 20 | S17: =CEILING('1. Assumptions'!K45/'1. Assumptions'!C9,1) -> 20 | T17: =CEILING('1. Assumptions'!K45/'1. Assumptions'!C9,1) -> 20 | U17: =CEILING('1. Assumptions'!K45/'1. Assumptions'!C9,1) -> 20 | V17: =CEILING('1. Assumptions'!K45/'1. Assumptions'!C9,1) -> 20 | W17: =CEILING('1. Assumptions'!K45/'1. Assumptions'!C9,1) -> 20 | X17: =CEILING('1. Assumptions'!K45/'1. Assumptions'!C9,1) -> 20 | Y17: =CEILING('1. Assumptions'!K45/'1. Assumptions'!C9,1) -> 20 | Z17: =C17 -> 440
B18: Selects / Day | C18: ='1. Assumptions'!H25 -> 35 | D18: =CEILING('1. Assumptions'!H25/'1. Assumptions'!C9,1) -> 2 | E18: =CEILING('1. Assumptions'!H25/'1. Assumptions'!C9,1) -> 2 | F18: =CEILING('1. Assumptions'!H25/'1. Assumptions'!C9,1) -> 2 | G18: =CEILING('1. Assumptions'!H25/'1. Assumptions'!C9,1) -> 2 | H18: =CEILING('1. Assumptions'!H25/'1. Assumptions'!C9,1) -> 2 | I18: =CEILING('1. Assumptions'!H25/'1. Assumptions'!C9,1) -> 2 | J18: =CEILING('1. Assumptions'!H25/'1. Assumptions'!C9,1) -> 2 | K18: =CEILING('1. Assumptions'!H25/'1. Assumptions'!C9,1) -> 2 | L18: =CEILING('1. Assumptions'!H25/'1. Assumptions'!C9,1) -> 2 | M18: =CEILING('1. Assumptions'!H25/'1. Assumptions'!C9,1) -> 2 | N18: =CEILING('1. Assumptions'!H25/'1. Assumptions'!C9,1) -> 2 | O18: =CEILING('1. Assumptions'!H25/'1. Assumptions'!C9,1) -> 2 | P18: =CEILING('1. Assumptions'!H25/'1. Assumptions'!C9,1) -> 2 | Q18: =CEILING('1. Assumptions'!H25/'1. Assumptions'!C9,1) -> 2 | R18: =CEILING('1. Assumptions'!H25/'1. Assumptions'!C9,1) -> 2 | S18: =CEILING('1. Assumptions'!H25/'1. Assumptions'!C9,1) -> 2 | T18: =CEILING('1. Assumptions'!H25/'1. Assumptions'!C9,1) -> 2 | U18: =CEILING('1. Assumptions'!H25/'1. Assumptions'!C9,1) -> 2 | V18: =CEILING('1. Assumptions'!H25/'1. Assumptions'!C9,1) -> 2 | W18: =CEILING('1. Assumptions'!H25/'1. Assumptions'!C9,1) -> 2 | X18: =CEILING('1. Assumptions'!H25/'1. Assumptions'!C9,1) -> 2 | Y18: =CEILING('1. Assumptions'!H25/'1. Assumptions'!C9,1) -> 2 | Z18: =C18 -> 35
B19: OBs — Weekly Target (Fridays) | C19: ='1. Assumptions'!G25 -> 28 | D19: · | E19: · | F19: · | G19: · | H19: =ROUND(5/'1. Assumptions'!C9*'1. Assumptions'!G25,0)-ROUND(0/'1. Assumptions'!C9*'1. Assumptions'!G25,0) -> 6 | I19: · | J19: · | K19: · | L19: · | M19: =ROUND(10/'1. Assumptions'!C9*'1. Assumptions'!G25,0)-ROUND(5/'1. Assumptions'!C9*'1. Assumptions'!G25,0) -> 7 | N19: · | O19: · | P19: · | Q19: · | R19: =ROUND(15/'1. Assumptions'!C9*'1. Assumptions'!G25,0)-ROUND(10/'1. Assumptions'!C9*'1. Assumptions'!G25,0) -> 6 | S19: · | T19: · | U19: · | V19: · | W19: =ROUND(20/'1. Assumptions'!C9*'1. Assumptions'!G25,0)-ROUND(15/'1. Assumptions'!C9*'1. Assumptions'!G25,0) -> 6 | X19: · | Y19: =ROUND(22/'1. Assumptions'!C9*'1. Assumptions'!G25,0)-ROUND(20/'1. Assumptions'!C9*'1. Assumptions'!G25,0) -> 3 | Z19: =C19 -> 28
B21: DTICI
B22: Demand Pool | C22: ='1. Assumptions'!C36 -> 200 | D22: Repeat 80%: 160 demands x 4 subs = 640 subs | New 20%: 40 demands x (2+2) subs = 160 subs (Phase 1 days 1-11 / Phase 2 days 12-22 after validation)
B23: Subs / Day | C23: ='1. Assumptions'!J46 -> 800 | D23: =CEILING('1. Assumptions'!J46/'1. Assumptions'!C9,1) -> 37 | E23: =CEILING('1. Assumptions'!J46/'1. Assumptions'!C9,1) -> 37 | F23: =CEILING('1. Assumptions'!J46/'1. Assumptions'!C9,1) -> 37 | G23: =CEILING('1. Assumptions'!J46/'1. Assumptions'!C9,1) -> 37 | H23: =CEILING('1. Assumptions'!J46/'1. Assumptions'!C9,1) -> 37 | I23: =CEILING('1. Assumptions'!J46/'1. Assumptions'!C9,1) -> 37 | J23: =CEILING('1. Assumptions'!J46/'1. Assumptions'!C9,1) -> 37 | K23: =CEILING('1. Assumptions'!J46/'1. Assumptions'!C9,1) -> 37 | L23: =CEILING('1. Assumptions'!J46/'1. Assumptions'!C9,1) -> 37 | M23: =CEILING('1. Assumptions'!J46/'1. Assumptions'!C9,1) -> 37 | N23: =CEILING('1. Assumptions'!J46/'1. Assumptions'!C9,1) -> 37 | O23: =CEILING('1. Assumptions'!J46/'1. Assumptions'!C9,1) -> 37 | P23: =CEILING('1. Assumptions'!J46/'1. Assumptions'!C9,1) -> 37 | Q23: =CEILING('1. Assumptions'!J46/'1. Assumptions'!C9,1) -> 37 | R23: =CEILING('1. Assumptions'!J46/'1. Assumptions'!C9,1) -> 37 | S23: =CEILING('1. Assumptions'!J46/'1. Assumptions'!C9,1) -> 37 | T23: =CEILING('1. Assumptions'!J46/'1. Assumptions'!C9,1) -> 37 | U23: =CEILING('1. Assumptions'!J46/'1. Assumptions'!C9,1) -> 37 | V23: =CEILING('1. Assumptions'!J46/'1. Assumptions'!C9,1) -> 37 | W23: =CEILING('1. Assumptions'!J46/'1. Assumptions'!C9,1) -> 37 | X23: =CEILING('1. Assumptions'!J46/'1. Assumptions'!C9,1) -> 37 | Y23: =CEILING('1. Assumptions'!J46/'1. Assumptions'!C9,1) -> 37 | Z23: =C23 -> 800
B24: Interviews / Day | C24: ='1. Assumptions'!K46 -> 308 | D24: =CEILING('1. Assumptions'!K46/'1. Assumptions'!C9,1) -> 14 | E24: =CEILING('1. Assumptions'!K46/'1. Assumptions'!C9,1) -> 14 | F24: =CEILING('1. Assumptions'!K46/'1. Assumptions'!C9,1) -> 14 | G24: =CEILING('1. Assumptions'!K46/'1. Assumptions'!C9,1) -> 14 | H24: =CEILING('1. Assumptions'!K46/'1. Assumptions'!C9,1) -> 14 | I24: =CEILING('1. Assumptions'!K46/'1. Assumptions'!C9,1) -> 14 | J24: =CEILING('1. Assumptions'!K46/'1. Assumptions'!C9,1) -> 14 | K24: =CEILING('1. Assumptions'!K46/'1. Assumptions'!C9,1) -> 14 | L24: =CEILING('1. Assumptions'!K46/'1. Assumptions'!C9,1) -> 14 | M24: =CEILING('1. Assumptions'!K46/'1. Assumptions'!C9,1) -> 14 | N24: =CEILING('1. Assumptions'!K46/'1. Assumptions'!C9,1) -> 14 | O24: =CEILING('1. Assumptions'!K46/'1. Assumptions'!C9,1) -> 14 | P24: =CEILING('1. Assumptions'!K46/'1. Assumptions'!C9,1) -> 14 | Q24: =CEILING('1. Assumptions'!K46/'1. Assumptions'!C9,1) -> 14 | R24: =CEILING('1. Assumptions'!K46/'1. Assumptions'!C9,1) -> 14 | S24: =CEILING('1. Assumptions'!K46/'1. Assumptions'!C9,1) -> 14 | T24: =CEILING('1. Assumptions'!K46/'1. Assumptions'!C9,1) -> 14 | U24: =CEILING('1. Assumptions'!K46/'1. Assumptions'!C9,1) -> 14 | V24: =CEILING('1. Assumptions'!K46/'1. Assumptions'!C9,1) -> 14 | W24: =CEILING('1. Assumptions'!K46/'1. Assumptions'!C9,1) -> 14 | X24: =CEILING('1. Assumptions'!K46/'1. Assumptions'!C9,1) -> 14 | Y24: =CEILING('1. Assumptions'!K46/'1. Assumptions'!C9,1) -> 14 | Z24: =C24 -> 308
B25: Selects / Day | C25: ='1. Assumptions'!H26 -> 19 | D25: =CEILING('1. Assumptions'!H26/'1. Assumptions'!C9,1) -> 1 | E25: =CEILING('1. Assumptions'!H26/'1. Assumptions'!C9,1) -> 1 | F25: =CEILING('1. Assumptions'!H26/'1. Assumptions'!C9,1) -> 1 | G25: =CEILING('1. Assumptions'!H26/'1. Assumptions'!C9,1) -> 1 | H25: =CEILING('1. Assumptions'!H26/'1. Assumptions'!C9,1) -> 1 | I25: =CEILING('1. Assumptions'!H26/'1. Assumptions'!C9,1) -> 1 | J25: =CEILING('1. Assumptions'!H26/'1. Assumptions'!C9,1) -> 1 | K25: =CEILING('1. Assumptions'!H26/'1. Assumptions'!C9,1) -> 1 | L25: =CEILING('1. Assumptions'!H26/'1. Assumptions'!C9,1) -> 1 | M25: =CEILING('1. Assumptions'!H26/'1. Assumptions'!C9,1) -> 1 | N25: =CEILING('1. Assumptions'!H26/'1. Assumptions'!C9,1) -> 1 | O25: =CEILING('1. Assumptions'!H26/'1. Assumptions'!C9,1) -> 1 | P25: =CEILING('1. Assumptions'!H26/'1. Assumptions'!C9,1) -> 1 | Q25: =CEILING('1. Assumptions'!H26/'1. Assumptions'!C9,1) -> 1 | R25: =CEILING('1. Assumptions'!H26/'1. Assumptions'!C9,1) -> 1 | S25: =CEILING('1. Assumptions'!H26/'1. Assumptions'!C9,1) -> 1 | T25: =CEILING('1. Assumptions'!H26/'1. Assumptions'!C9,1) -> 1 | U25: =CEILING('1. Assumptions'!H26/'1. Assumptions'!C9,1) -> 1 | V25: =CEILING('1. Assumptions'!H26/'1. Assumptions'!C9,1) -> 1 | W25: =CEILING('1. Assumptions'!H26/'1. Assumptions'!C9,1) -> 1 | X25: =CEILING('1. Assumptions'!H26/'1. Assumptions'!C9,1) -> 1 | Y25: =CEILING('1. Assumptions'!H26/'1. Assumptions'!C9,1) -> 1 | Z25: =C25 -> 19
B26: OBs — Weekly Target (Fridays) | C26: ='1. Assumptions'!G26 -> 15 | D26: · | E26: · | F26: · | G26: · | H26: =ROUND(5/'1. Assumptions'!C9*'1. Assumptions'!G26,0)-ROUND(0/'1. Assumptions'!C9*'1. Assumptions'!G26,0) -> 3 | I26: · | J26: · | K26: · | L26: · | M26: =ROUND(10/'1. Assumptions'!C9*'1. Assumptions'!G26,0)-ROUND(5/'1. Assumptions'!C9*'1. Assumptions'!G26,0) -> 4 | N26: · | O26: · | P26: · | Q26: · | R26: =ROUND(15/'1. Assumptions'!C9*'1. Assumptions'!G26,0)-ROUND(10/'1. Assumptions'!C9*'1. Assumptions'!G26,0) -> 3 | S26: · | T26: · | U26: · | V26: · | W26: =ROUND(20/'1. Assumptions'!C9*'1. Assumptions'!G26,0)-ROUND(15/'1. Assumptions'!C9*'1. Assumptions'!G26,0) -> 4 | X26: · | Y26: =ROUND(22/'1. Assumptions'!C9*'1. Assumptions'!G26,0)-ROUND(20/'1. Assumptions'!C9*'1. Assumptions'!G26,0) -> 1 | Z26: =C26 -> 15
B28: BSH
B29: Demand Pool | C29: ='1. Assumptions'!C37 -> 60 | D29: Repeat 80%: 48 demands x 4 subs = 192 subs | New 20%: 12 demands x (2+2) subs = 48 subs (Phase 1 days 1-11 / Phase 2 days 12-22 after validation)
B30: Subs / Day | C30: ='1. Assumptions'!J47 -> 240 | D30: =CEILING('1. Assumptions'!J47/'1. Assumptions'!C9,1) -> 11 | E30: =CEILING('1. Assumptions'!J47/'1. Assumptions'!C9,1) -> 11 | F30: =CEILING('1. Assumptions'!J47/'1. Assumptions'!C9,1) -> 11 | G30: =CEILING('1. Assumptions'!J47/'1. Assumptions'!C9,1) -> 11 | H30: =CEILING('1. Assumptions'!J47/'1. Assumptions'!C9,1) -> 11 | I30: =CEILING('1. Assumptions'!J47/'1. Assumptions'!C9,1) -> 11 | J30: =CEILING('1. Assumptions'!J47/'1. Assumptions'!C9,1) -> 11 | K30: =CEILING('1. Assumptions'!J47/'1. Assumptions'!C9,1) -> 11 | L30: =CEILING('1. Assumptions'!J47/'1. Assumptions'!C9,1) -> 11 | M30: =CEILING('1. Assumptions'!J47/'1. Assumptions'!C9,1) -> 11 | N30: =CEILING('1. Assumptions'!J47/'1. Assumptions'!C9,1) -> 11 | O30: =CEILING('1. Assumptions'!J47/'1. Assumptions'!C9,1) -> 11 | P30: =CEILING('1. Assumptions'!J47/'1. Assumptions'!C9,1) -> 11 | Q30: =CEILING('1. Assumptions'!J47/'1. Assumptions'!C9,1) -> 11 | R30: =CEILING('1. Assumptions'!J47/'1. Assumptions'!C9,1) -> 11 | S30: =CEILING('1. Assumptions'!J47/'1. Assumptions'!C9,1) -> 11 | T30: =CEILING('1. Assumptions'!J47/'1. Assumptions'!C9,1) -> 11 | U30: =CEILING('1. Assumptions'!J47/'1. Assumptions'!C9,1) -> 11 | V30: =CEILING('1. Assumptions'!J47/'1. Assumptions'!C9,1) -> 11 | W30: =CEILING('1. Assumptions'!J47/'1. Assumptions'!C9,1) -> 11 | X30: =CEILING('1. Assumptions'!J47/'1. Assumptions'!C9,1) -> 11 | Y30: =CEILING('1. Assumptions'!J47/'1. Assumptions'!C9,1) -> 11 | Z30: =C30 -> 240
B31: Interviews / Day | C31: ='1. Assumptions'!K47 -> 154 | D31: =CEILING('1. Assumptions'!K47/'1. Assumptions'!C9,1) -> 7 | E31: =CEILING('1. Assumptions'!K47/'1. Assumptions'!C9,1) -> 7 | F31: =CEILING('1. Assumptions'!K47/'1. Assumptions'!C9,1) -> 7 | G31: =CEILING('1. Assumptions'!K47/'1. Assumptions'!C9,1) -> 7 | H31: =CEILING('1. Assumptions'!K47/'1. Assumptions'!C9,1) -> 7 | I31: =CEILING('1. Assumptions'!K47/'1. Assumptions'!C9,1) -> 7 | J31: =CEILING('1. Assumptions'!K47/'1. Assumptions'!C9,1) -> 7 | K31: =CEILING('1. Assumptions'!K47/'1. Assumptions'!C9,1) -> 7 | L31: =CEILING('1. Assumptions'!K47/'1. Assumptions'!C9,1) -> 7 | M31: =CEILING('1. Assumptions'!K47/'1. Assumptions'!C9,1) -> 7 | N31: =CEILING('1. Assumptions'!K47/'1. Assumptions'!C9,1) -> 7 | O31: =CEILING('1. Assumptions'!K47/'1. Assumptions'!C9,1) -> 7 | P31: =CEILING('1. Assumptions'!K47/'1. Assumptions'!C9,1) -> 7 | Q31: =CEILING('1. Assumptions'!K47/'1. Assumptions'!C9,1) -> 7 | R31: =CEILING('1. Assumptions'!K47/'1. Assumptions'!C9,1) -> 7 | S31: =CEILING('1. Assumptions'!K47/'1. Assumptions'!C9,1) -> 7 | T31: =CEILING('1. Assumptions'!K47/'1. Assumptions'!C9,1) -> 7 | U31: =CEILING('1. Assumptions'!K47/'1. Assumptions'!C9,1) -> 7 | V31: =CEILING('1. Assumptions'!K47/'1. Assumptions'!C9,1) -> 7 | W31: =CEILING('1. Assumptions'!K47/'1. Assumptions'!C9,1) -> 7 | X31: =CEILING('1. Assumptions'!K47/'1. Assumptions'!C9,1) -> 7 | Y31: =CEILING('1. Assumptions'!K47/'1. Assumptions'!C9,1) -> 7 | Z31: =C31 -> 154
B32: Selects / Day | C32: ='1. Assumptions'!H27 -> 12 | D32: =CEILING('1. Assumptions'!H27/'1. Assumptions'!C9,1) -> 1 | E32: =CEILING('1. Assumptions'!H27/'1. Assumptions'!C9,1) -> 1 | F32: =CEILING('1. Assumptions'!H27/'1. Assumptions'!C9,1) -> 1 | G32: =CEILING('1. Assumptions'!H27/'1. Assumptions'!C9,1) -> 1 | H32: =CEILING('1. Assumptions'!H27/'1. Assumptions'!C9,1) -> 1 | I32: =CEILING('1. Assumptions'!H27/'1. Assumptions'!C9,1) -> 1 | J32: =CEILING('1. Assumptions'!H27/'1. Assumptions'!C9,1) -> 1 | K32: =CEILING('1. Assumptions'!H27/'1. Assumptions'!C9,1) -> 1 | L32: =CEILING('1. Assumptions'!H27/'1. Assumptions'!C9,1) -> 1 | M32: =CEILING('1. Assumptions'!H27/'1. Assumptions'!C9,1) -> 1 | N32: =CEILING('1. Assumptions'!H27/'1. Assumptions'!C9,1) -> 1 | O32: =CEILING('1. Assumptions'!H27/'1. Assumptions'!C9,1) -> 1 | P32: =CEILING('1. Assumptions'!H27/'1. Assumptions'!C9,1) -> 1 | Q32: =CEILING('1. Assumptions'!H27/'1. Assumptions'!C9,1) -> 1 | R32: =CEILING('1. Assumptions'!H27/'1. Assumptions'!C9,1) -> 1 | S32: =CEILING('1. Assumptions'!H27/'1. Assumptions'!C9,1) -> 1 | T32: =CEILING('1. Assumptions'!H27/'1. Assumptions'!C9,1) -> 1 | U32: =CEILING('1. Assumptions'!H27/'1. Assumptions'!C9,1) -> 1 | V32: =CEILING('1. Assumptions'!H27/'1. Assumptions'!C9,1) -> 1 | W32: =CEILING('1. Assumptions'!H27/'1. Assumptions'!C9,1) -> 1 | X32: =CEILING('1. Assumptions'!H27/'1. Assumptions'!C9,1) -> 1 | Y32: =CEILING('1. Assumptions'!H27/'1. Assumptions'!C9,1) -> 1 | Z32: =C32 -> 12
B33: OBs — Weekly Target (Fridays) | C33: ='1. Assumptions'!G27 -> 9 | D33: · | E33: · | F33: · | G33: · | H33: =ROUND(5/'1. Assumptions'!C9*'1. Assumptions'!G27,0)-ROUND(0/'1. Assumptions'!C9*'1. Assumptions'!G27,0) -> 2 | I33: · | J33: · | K33: · | L33: · | M33: =ROUND(10/'1. Assumptions'!C9*'1. Assumptions'!G27,0)-ROUND(5/'1. Assumptions'!C9*'1. Assumptions'!G27,0) -> 2 | N33: · | O33: · | P33: · | Q33: · | R33: =ROUND(15/'1. Assumptions'!C9*'1. Assumptions'!G27,0)-ROUND(10/'1. Assumptions'!C9*'1. Assumptions'!G27,0) -> 2 | S33: · | T33: · | U33: · | V33: · | W33: =ROUND(20/'1. Assumptions'!C9*'1. Assumptions'!G27,0)-ROUND(15/'1. Assumptions'!C9*'1. Assumptions'!G27,0) -> 2 | X33: · | Y33: =ROUND(22/'1. Assumptions'!C9*'1. Assumptions'!G27,0)-ROUND(20/'1. Assumptions'!C9*'1. Assumptions'!G27,0) -> 1 | Z33: =C33 -> 9
B35: ARCELOR MITTAL
B36: Demand Pool | C36: ='1. Assumptions'!C38 -> 50 | D36: Repeat 80%: 40 demands x 4 subs = 160 subs | New 20%: 10 demands x (2+2) subs = 40 subs (Phase 1 days 1-11 / Phase 2 days 12-22 after validation)
B37: Subs / Day | C37: ='1. Assumptions'!J48 -> 200 | D37: =CEILING('1. Assumptions'!J48/'1. Assumptions'!C9,1) -> 10 | E37: =CEILING('1. Assumptions'!J48/'1. Assumptions'!C9,1) -> 10 | F37: =CEILING('1. Assumptions'!J48/'1. Assumptions'!C9,1) -> 10 | G37: =CEILING('1. Assumptions'!J48/'1. Assumptions'!C9,1) -> 10 | H37: =CEILING('1. Assumptions'!J48/'1. Assumptions'!C9,1) -> 10 | I37: =CEILING('1. Assumptions'!J48/'1. Assumptions'!C9,1) -> 10 | J37: =CEILING('1. Assumptions'!J48/'1. Assumptions'!C9,1) -> 10 | K37: =CEILING('1. Assumptions'!J48/'1. Assumptions'!C9,1) -> 10 | L37: =CEILING('1. Assumptions'!J48/'1. Assumptions'!C9,1) -> 10 | M37: =CEILING('1. Assumptions'!J48/'1. Assumptions'!C9,1) -> 10 | N37: =CEILING('1. Assumptions'!J48/'1. Assumptions'!C9,1) -> 10 | O37: =CEILING('1. Assumptions'!J48/'1. Assumptions'!C9,1) -> 10 | P37: =CEILING('1. Assumptions'!J48/'1. Assumptions'!C9,1) -> 10 | Q37: =CEILING('1. Assumptions'!J48/'1. Assumptions'!C9,1) -> 10 | R37: =CEILING('1. Assumptions'!J48/'1. Assumptions'!C9,1) -> 10 | S37: =CEILING('1. Assumptions'!J48/'1. Assumptions'!C9,1) -> 10 | T37: =CEILING('1. Assumptions'!J48/'1. Assumptions'!C9,1) -> 10 | U37: =CEILING('1. Assumptions'!J48/'1. Assumptions'!C9,1) -> 10 | V37: =CEILING('1. Assumptions'!J48/'1. Assumptions'!C9,1) -> 10 | W37: =CEILING('1. Assumptions'!J48/'1. Assumptions'!C9,1) -> 10 | X37: =CEILING('1. Assumptions'!J48/'1. Assumptions'!C9,1) -> 10 | Y37: =CEILING('1. Assumptions'!J48/'1. Assumptions'!C9,1) -> 10 | Z37: =C37 -> 200
B38: Interviews / Day | C38: ='1. Assumptions'!K48 -> 110 | D38: =CEILING('1. Assumptions'!K48/'1. Assumptions'!C9,1) -> 5 | E38: =CEILING('1. Assumptions'!K48/'1. Assumptions'!C9,1) -> 5 | F38: =CEILING('1. Assumptions'!K48/'1. Assumptions'!C9,1) -> 5 | G38: =CEILING('1. Assumptions'!K48/'1. Assumptions'!C9,1) -> 5 | H38: =CEILING('1. Assumptions'!K48/'1. Assumptions'!C9,1) -> 5 | I38: =CEILING('1. Assumptions'!K48/'1. Assumptions'!C9,1) -> 5 | J38: =CEILING('1. Assumptions'!K48/'1. Assumptions'!C9,1) -> 5 | K38: =CEILING('1. Assumptions'!K48/'1. Assumptions'!C9,1) -> 5 | L38: =CEILING('1. Assumptions'!K48/'1. Assumptions'!C9,1) -> 5 | M38: =CEILING('1. Assumptions'!K48/'1. Assumptions'!C9,1) -> 5 | N38: =CEILING('1. Assumptions'!K48/'1. Assumptions'!C9,1) -> 5 | O38: =CEILING('1. Assumptions'!K48/'1. Assumptions'!C9,1) -> 5 | P38: =CEILING('1. Assumptions'!K48/'1. Assumptions'!C9,1) -> 5 | Q38: =CEILING('1. Assumptions'!K48/'1. Assumptions'!C9,1) -> 5 | R38: =CEILING('1. Assumptions'!K48/'1. Assumptions'!C9,1) -> 5 | S38: =CEILING('1. Assumptions'!K48/'1. Assumptions'!C9,1) -> 5 | T38: =CEILING('1. Assumptions'!K48/'1. Assumptions'!C9,1) -> 5 | U38: =CEILING('1. Assumptions'!K48/'1. Assumptions'!C9,1) -> 5 | V38: =CEILING('1. Assumptions'!K48/'1. Assumptions'!C9,1) -> 5 | W38: =CEILING('1. Assumptions'!K48/'1. Assumptions'!C9,1) -> 5 | X38: =CEILING('1. Assumptions'!K48/'1. Assumptions'!C9,1) -> 5 | Y38: =CEILING('1. Assumptions'!K48/'1. Assumptions'!C9,1) -> 5 | Z38: =C38 -> 110
B39: Selects / Day | C39: ='1. Assumptions'!H28 -> 5 | D39: =CEILING('1. Assumptions'!H28/'1. Assumptions'!C9,1) -> 1 | E39: =CEILING('1. Assumptions'!H28/'1. Assumptions'!C9,1) -> 1 | F39: =CEILING('1. Assumptions'!H28/'1. Assumptions'!C9,1) -> 1 | G39: =CEILING('1. Assumptions'!H28/'1. Assumptions'!C9,1) -> 1 | H39: =CEILING('1. Assumptions'!H28/'1. Assumptions'!C9,1) -> 1 | I39: =CEILING('1. Assumptions'!H28/'1. Assumptions'!C9,1) -> 1 | J39: =CEILING('1. Assumptions'!H28/'1. Assumptions'!C9,1) -> 1 | K39: =CEILING('1. Assumptions'!H28/'1. Assumptions'!C9,1) -> 1 | L39: =CEILING('1. Assumptions'!H28/'1. Assumptions'!C9,1) -> 1 | M39: =CEILING('1. Assumptions'!H28/'1. Assumptions'!C9,1) -> 1 | N39: =CEILING('1. Assumptions'!H28/'1. Assumptions'!C9,1) -> 1 | O39: =CEILING('1. Assumptions'!H28/'1. Assumptions'!C9,1) -> 1 | P39: =CEILING('1. Assumptions'!H28/'1. Assumptions'!C9,1) -> 1 | Q39: =CEILING('1. Assumptions'!H28/'1. Assumptions'!C9,1) -> 1 | R39: =CEILING('1. Assumptions'!H28/'1. Assumptions'!C9,1) -> 1 | S39: =CEILING('1. Assumptions'!H28/'1. Assumptions'!C9,1) -> 1 | T39: =CEILING('1. Assumptions'!H28/'1. Assumptions'!C9,1) -> 1 | U39: =CEILING('1. Assumptions'!H28/'1. Assumptions'!C9,1) -> 1 | V39: =CEILING('1. Assumptions'!H28/'1. Assumptions'!C9,1) -> 1 | W39: =CEILING('1. Assumptions'!H28/'1. Assumptions'!C9,1) -> 1 | X39: =CEILING('1. Assumptions'!H28/'1. Assumptions'!C9,1) -> 1 | Y39: =CEILING('1. Assumptions'!H28/'1. Assumptions'!C9,1) -> 1 | Z39: =C39 -> 5
B40: OBs — Weekly Target (Fridays) | C40: ='1. Assumptions'!G28 -> 4 | D40: · | E40: · | F40: · | G40: · | H40: =ROUND(5/'1. Assumptions'!C9*'1. Assumptions'!G28,0)-ROUND(0/'1. Assumptions'!C9*'1. Assumptions'!G28,0) -> 1 | I40: · | J40: · | K40: · | L40: · | M40: =ROUND(10/'1. Assumptions'!C9*'1. Assumptions'!G28,0)-ROUND(5/'1. Assumptions'!C9*'1. Assumptions'!G28,0) -> 1 | N40: · | O40: · | P40: · | Q40: · | R40: =ROUND(15/'1. Assumptions'!C9*'1. Assumptions'!G28,0)-ROUND(10/'1. Assumptions'!C9*'1. Assumptions'!G28,0) -> 1 | S40: · | T40: · | U40: · | V40: · | W40: =ROUND(20/'1. Assumptions'!C9*'1. Assumptions'!G28,0)-ROUND(15/'1. Assumptions'!C9*'1. Assumptions'!G28,0) -> 1 | X40: · | Y40: =ROUND(22/'1. Assumptions'!C9*'1. Assumptions'!G28,0)-ROUND(20/'1. Assumptions'!C9*'1. Assumptions'!G28,0) -> 0 | Z40: =C40 -> 4
B42: PURE STORAGE
B43: Demand Pool | C43: ='1. Assumptions'!C39 -> 25 | D43: Repeat 80%: 20 demands x 4 subs = 80 subs | New 20%: 5 demands x (2+2) subs = 20 subs (Phase 1 days 1-11 / Phase 2 days 12-22 after validation)
B44: Subs / Day | C44: ='1. Assumptions'!J49 -> 100 | D44: =CEILING('1. Assumptions'!J49/'1. Assumptions'!C9,1) -> 5 | E44: =CEILING('1. Assumptions'!J49/'1. Assumptions'!C9,1) -> 5 | F44: =CEILING('1. Assumptions'!J49/'1. Assumptions'!C9,1) -> 5 | G44: =CEILING('1. Assumptions'!J49/'1. Assumptions'!C9,1) -> 5 | H44: =CEILING('1. Assumptions'!J49/'1. Assumptions'!C9,1) -> 5 | I44: =CEILING('1. Assumptions'!J49/'1. Assumptions'!C9,1) -> 5 | J44: =CEILING('1. Assumptions'!J49/'1. Assumptions'!C9,1) -> 5 | K44: =CEILING('1. Assumptions'!J49/'1. Assumptions'!C9,1) -> 5 | L44: =CEILING('1. Assumptions'!J49/'1. Assumptions'!C9,1) -> 5 | M44: =CEILING('1. Assumptions'!J49/'1. Assumptions'!C9,1) -> 5 | N44: =CEILING('1. Assumptions'!J49/'1. Assumptions'!C9,1) -> 5 | O44: =CEILING('1. Assumptions'!J49/'1. Assumptions'!C9,1) -> 5 | P44: =CEILING('1. Assumptions'!J49/'1. Assumptions'!C9,1) -> 5 | Q44: =CEILING('1. Assumptions'!J49/'1. Assumptions'!C9,1) -> 5 | R44: =CEILING('1. Assumptions'!J49/'1. Assumptions'!C9,1) -> 5 | S44: =CEILING('1. Assumptions'!J49/'1. Assumptions'!C9,1) -> 5 | T44: =CEILING('1. Assumptions'!J49/'1. Assumptions'!C9,1) -> 5 | U44: =CEILING('1. Assumptions'!J49/'1. Assumptions'!C9,1) -> 5 | V44: =CEILING('1. Assumptions'!J49/'1. Assumptions'!C9,1) -> 5 | W44: =CEILING('1. Assumptions'!J49/'1. Assumptions'!C9,1) -> 5 | X44: =CEILING('1. Assumptions'!J49/'1. Assumptions'!C9,1) -> 5 | Y44: =CEILING('1. Assumptions'!J49/'1. Assumptions'!C9,1) -> 5 | Z44: =C44 -> 100
B45: Interviews / Day | C45: ='1. Assumptions'!K49 -> 88 | D45: =CEILING('1. Assumptions'!K49/'1. Assumptions'!C9,1) -> 4 | E45: =CEILING('1. Assumptions'!K49/'1. Assumptions'!C9,1) -> 4 | F45: =CEILING('1. Assumptions'!K49/'1. Assumptions'!C9,1) -> 4 | G45: =CEILING('1. Assumptions'!K49/'1. Assumptions'!C9,1) -> 4 | H45: =CEILING('1. Assumptions'!K49/'1. Assumptions'!C9,1) -> 4 | I45: =CEILING('1. Assumptions'!K49/'1. Assumptions'!C9,1) -> 4 | J45: =CEILING('1. Assumptions'!K49/'1. Assumptions'!C9,1) -> 4 | K45: =CEILING('1. Assumptions'!K49/'1. Assumptions'!C9,1) -> 4 | L45: =CEILING('1. Assumptions'!K49/'1. Assumptions'!C9,1) -> 4 | M45: =CEILING('1. Assumptions'!K49/'1. Assumptions'!C9,1) -> 4 | N45: =CEILING('1. Assumptions'!K49/'1. Assumptions'!C9,1) -> 4 | O45: =CEILING('1. Assumptions'!K49/'1. Assumptions'!C9,1) -> 4 | P45: =CEILING('1. Assumptions'!K49/'1. Assumptions'!C9,1) -> 4 | Q45: =CEILING('1. Assumptions'!K49/'1. Assumptions'!C9,1) -> 4 | R45: =CEILING('1. Assumptions'!K49/'1. Assumptions'!C9,1) -> 4 | S45: =CEILING('1. Assumptions'!K49/'1. Assumptions'!C9,1) -> 4 | T45: =CEILING('1. Assumptions'!K49/'1. Assumptions'!C9,1) -> 4 | U45: =CEILING('1. Assumptions'!K49/'1. Assumptions'!C9,1) -> 4 | V45: =CEILING('1. Assumptions'!K49/'1. Assumptions'!C9,1) -> 4 | W45: =CEILING('1. Assumptions'!K49/'1. Assumptions'!C9,1) -> 4 | X45: =CEILING('1. Assumptions'!K49/'1. Assumptions'!C9,1) -> 4 | Y45: =CEILING('1. Assumptions'!K49/'1. Assumptions'!C9,1) -> 4 | Z45: =C45 -> 88
B46: Selects / Day | C46: ='1. Assumptions'!H29 -> 5 | D46: =CEILING('1. Assumptions'!H29/'1. Assumptions'!C9,1) -> 1 | E46: =CEILING('1. Assumptions'!H29/'1. Assumptions'!C9,1) -> 1 | F46: =CEILING('1. Assumptions'!H29/'1. Assumptions'!C9,1) -> 1 | G46: =CEILING('1. Assumptions'!H29/'1. Assumptions'!C9,1) -> 1 | H46: =CEILING('1. Assumptions'!H29/'1. Assumptions'!C9,1) -> 1 | I46: =CEILING('1. Assumptions'!H29/'1. Assumptions'!C9,1) -> 1 | J46: =CEILING('1. Assumptions'!H29/'1. Assumptions'!C9,1) -> 1 | K46: =CEILING('1. Assumptions'!H29/'1. Assumptions'!C9,1) -> 1 | L46: =CEILING('1. Assumptions'!H29/'1. Assumptions'!C9,1) -> 1 | M46: =CEILING('1. Assumptions'!H29/'1. Assumptions'!C9,1) -> 1 | N46: =CEILING('1. Assumptions'!H29/'1. Assumptions'!C9,1) -> 1 | O46: =CEILING('1. Assumptions'!H29/'1. Assumptions'!C9,1) -> 1 | P46: =CEILING('1. Assumptions'!H29/'1. Assumptions'!C9,1) -> 1 | Q46: =CEILING('1. Assumptions'!H29/'1. Assumptions'!C9,1) -> 1 | R46: =CEILING('1. Assumptions'!H29/'1. Assumptions'!C9,1) -> 1 | S46: =CEILING('1. Assumptions'!H29/'1. Assumptions'!C9,1) -> 1 | T46: =CEILING('1. Assumptions'!H29/'1. Assumptions'!C9,1) -> 1 | U46: =CEILING('1. Assumptions'!H29/'1. Assumptions'!C9,1) -> 1 | V46: =CEILING('1. Assumptions'!H29/'1. Assumptions'!C9,1) -> 1 | W46: =CEILING('1. Assumptions'!H29/'1. Assumptions'!C9,1) -> 1 | X46: =CEILING('1. Assumptions'!H29/'1. Assumptions'!C9,1) -> 1 | Y46: =CEILING('1. Assumptions'!H29/'1. Assumptions'!C9,1) -> 1 | Z46: =C46 -> 5
B47: OBs — Weekly Target (Fridays) | C47: ='1. Assumptions'!G29 -> 4 | D47: · | E47: · | F47: · | G47: · | H47: =ROUND(5/'1. Assumptions'!C9*'1. Assumptions'!G29,0)-ROUND(0/'1. Assumptions'!C9*'1. Assumptions'!G29,0) -> 1 | I47: · | J47: · | K47: · | L47: · | M47: =ROUND(10/'1. Assumptions'!C9*'1. Assumptions'!G29,0)-ROUND(5/'1. Assumptions'!C9*'1. Assumptions'!G29,0) -> 1 | N47: · | O47: · | P47: · | Q47: · | R47: =ROUND(15/'1. Assumptions'!C9*'1. Assumptions'!G29,0)-ROUND(10/'1. Assumptions'!C9*'1. Assumptions'!G29,0) -> 1 | S47: · | T47: · | U47: · | V47: · | W47: =ROUND(20/'1. Assumptions'!C9*'1. Assumptions'!G29,0)-ROUND(15/'1. Assumptions'!C9*'1. Assumptions'!G29,0) -> 1 | X47: · | Y47: =ROUND(22/'1. Assumptions'!C9*'1. Assumptions'!G29,0)-ROUND(20/'1. Assumptions'!C9*'1. Assumptions'!G29,0) -> 0 | Z47: =C47 -> 4
...
